<?xml version="1.0" ?>
<!-- =================================================================================== -->
<!-- |    This document was autogenerated by xacro from hummingbird.xacro              | -->
<!-- |    EDITING THIS FILE BY HAND IS NOT RECOMMENDED                                 | -->
<!-- =================================================================================== -->
<robot name="hummingbird" xmlns:xacro="http://ros.org/wiki/xacro">
  <link name="quad/base_link"/>
  <joint name="quad/base_joint" type="fixed">
    <origin rpy="0 0 0" xyz="0 0 0"/>
    <parent link="quad/base_link"/>
    <child link="quad/base_link_inertia"/>
  </joint>
  <link name="quad/base_link_inertia">
    <inertial>
      <mass value="0.68"/>
      <!-- [kg] -->
      <origin xyz="0 0 0"/>
      <inertia ixx="0.007" ixy="0.0" ixz="0.0" iyy="0.007" iyz="0.0" izz="0.012"/>
    </inertial>
    <visual>
      <origin rpy="0 0 0" xyz="0 0 0"/>
      <geometry>
        <mesh filename="package://rotors_description/meshes/hummingbird.dae" scale="1 1 1"/>
      </geometry>
    </visual>
    <collision>
      <origin rpy="0 0 0" xyz="0 0 0"/>
      <geometry>
        <box size="0.1 0.1 0.12"/>
        <!-- [m] [m] [m] -->
      </geometry>
    </collision>
  </link>
  <!-- attach multirotor_base_plugin to the base_link -->
  <gazebo>
    <plugin filename="librotors_gazebo_multirotor_base_plugin.so" name="multirotor_base_plugin">
      <robotNamespace>quad</robotNamespace>
      <linkName>quad/base_link</linkName>
      <rotorVelocitySlowdownSim>10</rotorVelocitySlowdownSim>
    </plugin>
  </gazebo>
  <joint name="quad/rotor_0_joint" type="continuous">
    <origin rpy="0 0 0" xyz="0.17 0 0.01"/>
    <axis xyz="0 0 1"/>
    <!-- TODO(ff): not currently set because it's not yet supported -->
    <!-- <limit effort="2000" velocity="${max_rot_velocity}" /> -->
    <parent link="quad/base_link"/>
    <child link="quad/rotor_0"/>
  </joint>
  <link name="quad/rotor_0">
    <inertial>
      <mass value="0.009"/>
      <!-- [kg] -->
      <inertia ixx="1.754999298e-06" ixy="0.0" ixz="0.0" iyy="7.5067469973e-05" iyz="0.0" izz="7.6687469325e-05"/>
    </inertial>
    <visual>
      <geometry>
        <mesh filename="package://rotors_description/meshes/propeller_cw.dae" scale="0.1 0.1 0.1"/>
        <!-- The propeller meshes have a radius of 1m -->
        <!-- <box size="${2*radius_rotor} 0.01 0.005"/> -->
      </geometry>
    </visual>
    <collision>
      <geometry>
        <cylinder length="0.005" radius="0.1"/>
        <!-- [m] -->
      </geometry>
    </collision>
  </link>
  <gazebo>
    <plugin filename="librotors_gazebo_motor_model.so" name="quad_front_motor_model">
      <robotNamespace>quad</robotNamespace>
      <jointName>quad/rotor_0_joint</jointName>
      <linkName>quad/rotor_0</linkName>
      <turningDirection>cw</turningDirection>
      <timeConstantUp>0.0125</timeConstantUp>
      <timeConstantDown>0.025</timeConstantDown>
      <maxRotVelocity>838</maxRotVelocity>
      <motorConstant>8.54858e-06</motorConstant>
      <momentConstant>0.016</momentConstant>
      <commandSubTopic>gazebo/command/motor_speed</commandSubTopic>
      <motorNumber>0</motorNumber>
      <rotorDragCoefficient>8.06428e-05</rotorDragCoefficient>
      <rollingMomentCoefficient>1e-06</rollingMomentCoefficient>
      <motorSpeedPubTopic>motor_speed/0</motorSpeedPubTopic>
      <rotorVelocitySlowdownSim>10</rotorVelocitySlowdownSim>
    </plugin>
  </gazebo>
  <gazebo reference="quad/rotor_0">
    <material>Gazebo/Red</material>
  </gazebo>
  <joint name="quad/rotor_1_joint" type="continuous">
    <origin rpy="0 0 0" xyz="0 0.17 0.01"/>
    <axis xyz="0 0 1"/>
    <!-- TODO(ff): not currently set because it's not yet supported -->
    <!-- <limit effort="2000" velocity="${max_rot_velocity}" /> -->
    <parent link="quad/base_link"/>
    <child link="quad/rotor_1"/>
  </joint>
  <link name="quad/rotor_1">
    <inertial>
      <mass value="0.009"/>
      <!-- [kg] -->
      <inertia ixx="1.754999298e-06" ixy="0.0" ixz="0.0" iyy="7.5067469973e-05" iyz="0.0" izz="7.6687469325e-05"/>
    </inertial>
    <visual>
      <geometry>
        <mesh filename="package://rotors_description/meshes/propeller_ccw.dae" scale="0.1 0.1 0.1"/>
        <!-- The propeller meshes have a radius of 1m -->
        <!-- <box size="${2*radius_rotor} 0.01 0.005"/> -->
      </geometry>
    </visual>
    <collision>
      <geometry>
        <cylinder length="0.005" radius="0.1"/>
        <!-- [m] -->
      </geometry>
    </collision>
  </link>
  <gazebo>
    <plugin filename="librotors_gazebo_motor_model.so" name="quad_left_motor_model">
      <robotNamespace>quad</robotNamespace>
      <jointName>quad/rotor_1_joint</jointName>
      <linkName>quad/rotor_1</linkName>
      <turningDirection>ccw</turningDirection>
      <timeConstantUp>0.0125</timeConstantUp>
      <timeConstantDown>0.025</timeConstantDown>
      <maxRotVelocity>838</maxRotVelocity>
      <motorConstant>8.54858e-06</motorConstant>
      <momentConstant>0.016</momentConstant>
      <commandSubTopic>gazebo/command/motor_speed</commandSubTopic>
      <motorNumber>1</motorNumber>
      <rotorDragCoefficient>8.06428e-05</rotorDragCoefficient>
      <rollingMomentCoefficient>1e-06</rollingMomentCoefficient>
      <motorSpeedPubTopic>motor_speed/1</motorSpeedPubTopic>
      <rotorVelocitySlowdownSim>10</rotorVelocitySlowdownSim>
    </plugin>
  </gazebo>
  <gazebo reference="quad/rotor_1">
    <material>Gazebo/Blue</material>
  </gazebo>
  <joint name="quad/rotor_2_joint" type="continuous">
    <origin rpy="0 0 0" xyz="-0.17 0 0.01"/>
    <axis xyz="0 0 1"/>
    <!-- TODO(ff): not currently set because it's not yet supported -->
    <!-- <limit effort="2000" velocity="${max_rot_velocity}" /> -->
    <parent link="quad/base_link"/>
    <child link="quad/rotor_2"/>
  </joint>
  <link name="quad/rotor_2">
    <inertial>
      <mass value="0.009"/>
      <!-- [kg] -->
      <inertia ixx="1.754999298e-06" ixy="0.0" ixz="0.0" iyy="7.5067469973e-05" iyz="0.0" izz="7.6687469325e-05"/>
    </inertial>
    <visual>
      <geometry>
        <mesh filename="package://rotors_description/meshes/propeller_cw.dae" scale="0.1 0.1 0.1"/>
        <!-- The propeller meshes have a radius of 1m -->
        <!-- <box size="${2*radius_rotor} 0.01 0.005"/> -->
      </geometry>
    </visual>
    <collision>
      <geometry>
        <cylinder length="0.005" radius="0.1"/>
        <!-- [m] -->
      </geometry>
    </collision>
  </link>
  <gazebo>
    <plugin filename="librotors_gazebo_motor_model.so" name="quad_back_motor_model">
      <robotNamespace>quad</robotNamespace>
      <jointName>quad/rotor_2_joint</jointName>
      <linkName>quad/rotor_2</linkName>
      <turningDirection>cw</turningDirection>
      <timeConstantUp>0.0125</timeConstantUp>
      <timeConstantDown>0.025</timeConstantDown>
      <maxRotVelocity>838</maxRotVelocity>
      <motorConstant>8.54858e-06</motorConstant>
      <momentConstant>0.016</momentConstant>
      <commandSubTopic>gazebo/command/motor_speed</commandSubTopic>
      <motorNumber>2</motorNumber>
      <rotorDragCoefficient>8.06428e-05</rotorDragCoefficient>
      <rollingMomentCoefficient>1e-06</rollingMomentCoefficient>
      <motorSpeedPubTopic>motor_speed/2</motorSpeedPubTopic>
      <rotorVelocitySlowdownSim>10</rotorVelocitySlowdownSim>
    </plugin>
  </gazebo>
  <gazebo reference="quad/rotor_2">
    <material>Gazebo/Blue</material>
  </gazebo>
  <joint name="quad/rotor_3_joint" type="continuous">
    <origin rpy="0 0 0" xyz="0 -0.17 0.01"/>
    <axis xyz="0 0 1"/>
    <!-- TODO(ff): not currently set because it's not yet supported -->
    <!-- <limit effort="2000" velocity="${max_rot_velocity}" /> -->
    <parent link="quad/base_link"/>
    <child link="quad/rotor_3"/>
  </joint>
  <link name="quad/rotor_3">
    <inertial>
      <mass value="0.009"/>
      <!-- [kg] -->
      <inertia ixx="1.754999298e-06" ixy="0.0" ixz="0.0" iyy="7.5067469973e-05" iyz="0.0" izz="7.6687469325e-05"/>
    </inertial>
    <visual>
      <geometry>
        <mesh filename="package://rotors_description/meshes/propeller_ccw.dae" scale="0.1 0.1 0.1"/>
        <!-- The propeller meshes have a radius of 1m -->
        <!-- <box size="${2*radius_rotor} 0.01 0.005"/> -->
      </geometry>
    </visual>
    <collision>
      <geometry>
        <cylinder length="0.005" radius="0.1"/>
        <!-- [m] -->
      </geometry>
    </collision>
  </link>
  <gazebo>
    <plugin filename="librotors_gazebo_motor_model.so" name="quad_right_motor_model">
      <robotNamespace>quad</robotNamespace>
      <jointName>quad/rotor_3_joint</jointName>
      <linkName>quad/rotor_3</linkName>
      <turningDirection>ccw</turningDirection>
      <timeConstantUp>0.0125</timeConstantUp>
      <timeConstantDown>0.025</timeConstantDown>
      <maxRotVelocity>838</maxRotVelocity>
      <motorConstant>8.54858e-06</motorConstant>
      <momentConstant>0.016</momentConstant>
      <commandSubTopic>gazebo/command/motor_speed</commandSubTopic>
      <motorNumber>3</motorNumber>
      <rotorDragCoefficient>8.06428e-05</rotorDragCoefficient>
      <rollingMomentCoefficient>1e-06</rollingMomentCoefficient>
      <motorSpeedPubTopic>motor_speed/3</motorSpeedPubTopic>
      <rotorVelocitySlowdownSim>10</rotorVelocitySlowdownSim>
    </plugin>
  </gazebo>
  <gazebo reference="quad/rotor_3">
    <material>Gazebo/Blue</material>
  </gazebo>
</robot>
